[2024-08-09T09:34:17.834+0000] {local_task_job_runner.py:120} INFO - ::group::Pre task execution logs
[2024-08-09T09:34:17.868+0000] {taskinstance.py:2076} INFO - Dependencies all met for dep_context=non-requeueable deps ti=<TaskInstance: Integrate_Data_Warehouse.gold_atvsld manual__2024-08-09T09:33:18.751104+00:00 [queued]>
[2024-08-09T09:34:17.883+0000] {taskinstance.py:2076} INFO - Dependencies all met for dep_context=requeueable deps ti=<TaskInstance: Integrate_Data_Warehouse.gold_atvsld manual__2024-08-09T09:33:18.751104+00:00 [queued]>
[2024-08-09T09:34:17.884+0000] {taskinstance.py:2306} INFO - Starting attempt 1 of 1
[2024-08-09T09:34:17.925+0000] {taskinstance.py:2330} INFO - Executing <Task(PythonOperator): gold_atvsld> on 2024-08-09 09:33:18.751104+00:00
[2024-08-09T09:34:17.933+0000] {standard_task_runner.py:63} INFO - Started process 5899 to run task
[2024-08-09T09:34:17.938+0000] {standard_task_runner.py:90} INFO - Running: ['airflow', 'tasks', 'run', 'Integrate_Data_Warehouse', 'gold_atvsld', 'manual__2024-08-09T09:33:18.751104+00:00', '--job-id', '445', '--raw', '--subdir', 'DAGS_FOLDER/etl_ldtbxh.dag.py', '--cfg-path', '/tmp/tmpxeb53zhp']
[2024-08-09T09:34:17.940+0000] {standard_task_runner.py:91} INFO - Job 445: Subtask gold_atvsld
[2024-08-09T09:34:18.023+0000] {task_command.py:426} INFO - Running <TaskInstance: Integrate_Data_Warehouse.gold_atvsld manual__2024-08-09T09:33:18.751104+00:00 [running]> on host 45f7764b2bf2
[2024-08-09T09:34:18.176+0000] {taskinstance.py:2648} INFO - Exporting env vars: AIRFLOW_CTX_DAG_OWNER='airflow' AIRFLOW_CTX_DAG_ID='Integrate_Data_Warehouse' AIRFLOW_CTX_TASK_ID='gold_atvsld' AIRFLOW_CTX_EXECUTION_DATE='2024-08-09T09:33:18.751104+00:00' AIRFLOW_CTX_TRY_NUMBER='1' AIRFLOW_CTX_DAG_RUN_ID='manual__2024-08-09T09:33:18.751104+00:00'
[2024-08-09T09:34:18.177+0000] {taskinstance.py:430} INFO - ::endgroup::
[2024-08-09T09:34:30.962+0000] {taskinstance.py:441} INFO - ::group::Post task execution logs
[2024-08-09T09:34:30.963+0000] {taskinstance.py:2905} ERROR - Task failed with exception
Traceback (most recent call last):
  File "/home/airflow/.local/lib/python3.11/site-packages/airflow/models/taskinstance.py", line 465, in _execute_task
    result = _execute_callable(context=context, **execute_callable_kwargs)
             ^^^^^^^^^^^^^^^^^^^^^^^^^^^^^^^^^^^^^^^^^^^^^^^^^^^^^^^^^^^^^
  File "/home/airflow/.local/lib/python3.11/site-packages/airflow/models/taskinstance.py", line 432, in _execute_callable
    return execute_callable(context=context, **execute_callable_kwargs)
           ^^^^^^^^^^^^^^^^^^^^^^^^^^^^^^^^^^^^^^^^^^^^^^^^^^^^^^^^^^^^
  File "/home/airflow/.local/lib/python3.11/site-packages/airflow/models/baseoperator.py", line 400, in wrapper
    return func(self, *args, **kwargs)
           ^^^^^^^^^^^^^^^^^^^^^^^^^^^
  File "/home/airflow/.local/lib/python3.11/site-packages/airflow/operators/python.py", line 235, in execute
    return_value = self.execute_callable()
                   ^^^^^^^^^^^^^^^^^^^^^^^
  File "/home/airflow/.local/lib/python3.11/site-packages/airflow/operators/python.py", line 252, in execute_callable
    return self.python_callable(*self.op_args, **self.op_kwargs)
           ^^^^^^^^^^^^^^^^^^^^^^^^^^^^^^^^^^^^^^^^^^^^^^^^^^^^^
  File "/opt/airflow/plugins/gold/atvsld_gold.py", line 29, in run_gold_atvsld
    finalfact_df.write.mode("overwrite").saveAsTable('stgMemberSurveyFact')
  File "/home/airflow/.local/lib/python3.11/site-packages/pyspark/sql/readwriter.py", line 1586, in saveAsTable
    self._jwrite.saveAsTable(name)
  File "/home/airflow/.local/lib/python3.11/site-packages/py4j/java_gateway.py", line 1322, in __call__
    return_value = get_return_value(
                   ^^^^^^^^^^^^^^^^^
  File "/home/airflow/.local/lib/python3.11/site-packages/pyspark/errors/exceptions/captured.py", line 185, in deco
    raise converted from None
pyspark.errors.exceptions.captured.SparkRuntimeException: [LOCATION_ALREADY_EXISTS] Cannot name the managed table as `spark_catalog`.`default`.`stgmembersurveyfact`, as its associated location 'file:/opt/airflow/spark-warehouse/stgmembersurveyfact' already exists. Please pick a different table name, or remove the existing location first.
[2024-08-09T09:34:31.009+0000] {taskinstance.py:1206} INFO - Marking task as FAILED. dag_id=Integrate_Data_Warehouse, task_id=gold_atvsld, run_id=manual__2024-08-09T09:33:18.751104+00:00, execution_date=20240809T093318, start_date=20240809T093417, end_date=20240809T093431
[2024-08-09T09:34:31.154+0000] {standard_task_runner.py:110} ERROR - Failed to execute job 445 for task gold_atvsld ([LOCATION_ALREADY_EXISTS] Cannot name the managed table as `spark_catalog`.`default`.`stgmembersurveyfact`, as its associated location 'file:/opt/airflow/spark-warehouse/stgmembersurveyfact' already exists. Please pick a different table name, or remove the existing location first.; 5899)
[2024-08-09T09:34:31.221+0000] {local_task_job_runner.py:240} INFO - Task exited with return code 1
[2024-08-09T09:34:31.305+0000] {taskinstance.py:3498} INFO - 0 downstream tasks scheduled from follow-on schedule check
[2024-08-09T09:34:31.389+0000] {local_task_job_runner.py:222} INFO - ::endgroup::
