[2024-08-02T10:00:56.871+0000] {local_task_job_runner.py:120} INFO - ::group::Pre task execution logs
[2024-08-02T10:00:56.905+0000] {taskinstance.py:2076} INFO - Dependencies all met for dep_context=non-requeueable deps ti=<TaskInstance: welcome_dag.query_postgres_database manual__2024-08-02T10:00:07.858891+00:00 [queued]>
[2024-08-02T10:00:56.921+0000] {taskinstance.py:2076} INFO - Dependencies all met for dep_context=requeueable deps ti=<TaskInstance: welcome_dag.query_postgres_database manual__2024-08-02T10:00:07.858891+00:00 [queued]>
[2024-08-02T10:00:56.922+0000] {taskinstance.py:2306} INFO - Starting attempt 1 of 1
[2024-08-02T10:00:56.959+0000] {taskinstance.py:2330} INFO - Executing <Task(SQLExecuteQueryOperator): query_postgres_database> on 2024-08-02 10:00:07.858891+00:00
[2024-08-02T10:00:56.964+0000] {standard_task_runner.py:63} INFO - Started process 1451 to run task
[2024-08-02T10:00:56.968+0000] {standard_task_runner.py:90} INFO - Running: ['airflow', 'tasks', 'run', 'welcome_dag', 'query_postgres_database', 'manual__2024-08-02T10:00:07.858891+00:00', '--job-id', '96', '--raw', '--subdir', 'DAGS_FOLDER/welcome_dag.py', '--cfg-path', '/tmp/tmpw1pmo5k3']
[2024-08-02T10:00:56.971+0000] {standard_task_runner.py:91} INFO - Job 96: Subtask query_postgres_database
[2024-08-02T10:00:57.054+0000] {task_command.py:426} INFO - Running <TaskInstance: welcome_dag.query_postgres_database manual__2024-08-02T10:00:07.858891+00:00 [running]> on host 24fc876e8f70
[2024-08-02T10:00:57.203+0000] {taskinstance.py:2648} INFO - Exporting env vars: AIRFLOW_CTX_DAG_OWNER='airflow' AIRFLOW_CTX_DAG_ID='welcome_dag' AIRFLOW_CTX_TASK_ID='query_postgres_database' AIRFLOW_CTX_EXECUTION_DATE='2024-08-02T10:00:07.858891+00:00' AIRFLOW_CTX_TRY_NUMBER='1' AIRFLOW_CTX_DAG_RUN_ID='manual__2024-08-02T10:00:07.858891+00:00'
[2024-08-02T10:00:57.204+0000] {taskinstance.py:430} INFO - ::endgroup::
[2024-08-02T10:00:57.219+0000] {sql.py:276} INFO - Executing: SELECT * FROM public.family_member_info;
[2024-08-02T10:00:57.236+0000] {base.py:84} INFO - Using connection ID 'postgres_default' for task execution.
[2024-08-02T10:00:57.393+0000] {base.py:84} INFO - Using connection ID 'postgres_default' for task execution.
[2024-08-02T10:00:57.395+0000] {taskinstance.py:441} INFO - ::group::Post task execution logs
[2024-08-02T10:00:57.396+0000] {taskinstance.py:2905} ERROR - Task failed with exception
Traceback (most recent call last):
  File "/home/airflow/.local/lib/python3.11/site-packages/airflow/models/taskinstance.py", line 465, in _execute_task
    result = _execute_callable(context=context, **execute_callable_kwargs)
             ^^^^^^^^^^^^^^^^^^^^^^^^^^^^^^^^^^^^^^^^^^^^^^^^^^^^^^^^^^^^^
  File "/home/airflow/.local/lib/python3.11/site-packages/airflow/models/taskinstance.py", line 432, in _execute_callable
    return execute_callable(context=context, **execute_callable_kwargs)
           ^^^^^^^^^^^^^^^^^^^^^^^^^^^^^^^^^^^^^^^^^^^^^^^^^^^^^^^^^^^^
  File "/home/airflow/.local/lib/python3.11/site-packages/airflow/models/baseoperator.py", line 400, in wrapper
    return func(self, *args, **kwargs)
           ^^^^^^^^^^^^^^^^^^^^^^^^^^^
  File "/home/airflow/.local/lib/python3.11/site-packages/airflow/providers/common/sql/operators/sql.py", line 282, in execute
    output = hook.run(
             ^^^^^^^^^
  File "/home/airflow/.local/lib/python3.11/site-packages/airflow/providers/common/sql/hooks/sql.py", line 411, in run
    with closing(self.get_conn()) as conn:
                 ^^^^^^^^^^^^^^^
  File "/home/airflow/.local/lib/python3.11/site-packages/airflow/providers/postgres/hooks/postgres.py", line 161, in get_conn
    self.conn = psycopg2.connect(**conn_args)
                ^^^^^^^^^^^^^^^^^^^^^^^^^^^^^
  File "/home/airflow/.local/lib/python3.11/site-packages/psycopg2/__init__.py", line 122, in connect
    conn = _connect(dsn, connection_factory=connection_factory, **kwasync)
           ^^^^^^^^^^^^^^^^^^^^^^^^^^^^^^^^^^^^^^^^^^^^^^^^^^^^^^^^^^^^^^^
psycopg2.OperationalError: connection to server at "localhost" (127.0.0.1), port 5432 failed: Connection refused
	Is the server running on that host and accepting TCP/IP connections?
connection to server at "localhost" (::1), port 5432 failed: Cannot assign requested address
	Is the server running on that host and accepting TCP/IP connections?

[2024-08-02T10:00:57.411+0000] {taskinstance.py:1206} INFO - Marking task as FAILED. dag_id=welcome_dag, task_id=query_postgres_database, run_id=manual__2024-08-02T10:00:07.858891+00:00, execution_date=20240802T100007, start_date=20240802T100056, end_date=20240802T100057
[2024-08-02T10:00:57.451+0000] {standard_task_runner.py:110} ERROR - Failed to execute job 96 for task query_postgres_database (connection to server at "localhost" (127.0.0.1), port 5432 failed: Connection refused
	Is the server running on that host and accepting TCP/IP connections?
connection to server at "localhost" (::1), port 5432 failed: Cannot assign requested address
	Is the server running on that host and accepting TCP/IP connections?
; 1451)
[2024-08-02T10:00:57.466+0000] {local_task_job_runner.py:240} INFO - Task exited with return code 1
[2024-08-02T10:00:57.505+0000] {taskinstance.py:3498} INFO - 0 downstream tasks scheduled from follow-on schedule check
[2024-08-02T10:00:57.532+0000] {local_task_job_runner.py:222} INFO - ::endgroup::
