[2024-08-09T07:14:25.834+0000] {local_task_job_runner.py:120} INFO - ::group::Pre task execution logs
[2024-08-09T07:14:25.869+0000] {taskinstance.py:2076} INFO - Dependencies all met for dep_context=non-requeueable deps ti=<TaskInstance: Integrate_Data_Warehouse.refresh_stages manual__2024-08-09T07:13:50.906281+00:00 [queued]>
[2024-08-09T07:14:25.883+0000] {taskinstance.py:2076} INFO - Dependencies all met for dep_context=requeueable deps ti=<TaskInstance: Integrate_Data_Warehouse.refresh_stages manual__2024-08-09T07:13:50.906281+00:00 [queued]>
[2024-08-09T07:14:25.884+0000] {taskinstance.py:2306} INFO - Starting attempt 1 of 1
[2024-08-09T07:14:25.918+0000] {taskinstance.py:2330} INFO - Executing <Task(SQLExecuteQueryOperator): refresh_stages> on 2024-08-09 07:13:50.906281+00:00
[2024-08-09T07:14:25.922+0000] {standard_task_runner.py:63} INFO - Started process 832 to run task
[2024-08-09T07:14:25.922+0000] {clientserver.py:543} INFO - Closing down clientserver connection
[2024-08-09T07:14:25.929+0000] {standard_task_runner.py:90} INFO - Running: ['airflow', 'tasks', 'run', 'Integrate_Data_Warehouse', 'refresh_stages', 'manual__2024-08-09T07:13:50.906281+00:00', '--job-id', '375', '--raw', '--subdir', 'DAGS_FOLDER/etl_ldtbxh.dag.py', '--cfg-path', '/tmp/tmpwhydkf85']
[2024-08-09T07:14:25.932+0000] {standard_task_runner.py:91} INFO - Job 375: Subtask refresh_stages
[2024-08-09T07:14:26.043+0000] {task_command.py:426} INFO - Running <TaskInstance: Integrate_Data_Warehouse.refresh_stages manual__2024-08-09T07:13:50.906281+00:00 [running]> on host 45f7764b2bf2
[2024-08-09T07:14:26.043+0000] {clientserver.py:505} INFO - Error while sending or receiving.
Traceback (most recent call last):
  File "/home/airflow/.local/lib/python3.11/site-packages/py4j/clientserver.py", line 503, in send_command
    self.socket.sendall(command.encode("utf-8"))
ConnectionResetError: [Errno 104] Connection reset by peer
[2024-08-09T07:14:26.051+0000] {clientserver.py:543} INFO - Closing down clientserver connection
[2024-08-09T07:14:26.052+0000] {java_gateway.py:1052} INFO - Exception while sending command.
Traceback (most recent call last):
  File "/home/airflow/.local/lib/python3.11/site-packages/py4j/clientserver.py", line 503, in send_command
    self.socket.sendall(command.encode("utf-8"))
ConnectionResetError: [Errno 104] Connection reset by peer

During handling of the above exception, another exception occurred:

Traceback (most recent call last):
  File "/home/airflow/.local/lib/python3.11/site-packages/py4j/java_gateway.py", line 1038, in send_command
    response = connection.send_command(command)
               ^^^^^^^^^^^^^^^^^^^^^^^^^^^^^^^^
  File "/home/airflow/.local/lib/python3.11/site-packages/py4j/clientserver.py", line 506, in send_command
    raise Py4JNetworkError(
py4j.protocol.Py4JNetworkError: Error while sending
[2024-08-09T07:14:26.061+0000] {clientserver.py:543} INFO - Closing down clientserver connection
[2024-08-09T07:14:26.260+0000] {taskinstance.py:2648} INFO - Exporting env vars: AIRFLOW_CTX_DAG_OWNER='airflow' AIRFLOW_CTX_DAG_ID='Integrate_Data_Warehouse' AIRFLOW_CTX_TASK_ID='refresh_stages' AIRFLOW_CTX_EXECUTION_DATE='2024-08-09T07:13:50.906281+00:00' AIRFLOW_CTX_TRY_NUMBER='1' AIRFLOW_CTX_DAG_RUN_ID='manual__2024-08-09T07:13:50.906281+00:00'
[2024-08-09T07:14:26.261+0000] {taskinstance.py:430} INFO - ::endgroup::
[2024-08-09T07:14:26.282+0000] {sql.py:276} INFO - Executing: TRUNCATE TABLE public."stgDate";
TRUNCATE TABLE public."stgDimLocation";
TRUNCATE TABLE public."stgDimFamily";
TRUNCATE TABLE public."stgDimFamilyMember";
TRUNCATE TABLE public."stgDimSurvey";
TRUNCATE TABLE public."stgPovertyStatusFact";
TRUNCATE TABLE public."stgMemberSurveyFact";

BEGIN TRANSACTION;
    INSERT INTO "DimAuditForeigned"(process_name, start_at, finished_at) VALUES
    ('data integration', NOW(), NULL);
COMMIT;
[2024-08-09T07:14:26.300+0000] {base.py:84} INFO - Using connection ID 'postgres_ldtbxh_stage' for task execution.
[2024-08-09T07:14:26.441+0000] {base.py:84} INFO - Using connection ID 'postgres_ldtbxh_stage' for task execution.
[2024-08-09T07:14:26.498+0000] {sql.py:470} INFO - Running statement: TRUNCATE TABLE public."stgDate";
TRUNCATE TABLE public."stgDimLocation";
TRUNCATE TABLE public."stgDimFamily";
TRUNCATE TABLE public."stgDimFamilyMember";
TRUNCATE TABLE public."stgDimSurvey";
TRUNCATE TABLE public."stgPovertyStatusFact";
TRUNCATE TABLE public."stgMemberSurveyFact";

BEGIN TRANSACTION;
    INSERT INTO "DimAuditForeigned"(process_name, start_at, finished_at) VALUES
    ('data integration', NOW(), NULL);
COMMIT;, parameters: None
[2024-08-09T07:14:26.709+0000] {taskinstance.py:441} INFO - ::group::Post task execution logs
[2024-08-09T07:14:26.729+0000] {taskinstance.py:1206} INFO - Marking task as SUCCESS. dag_id=Integrate_Data_Warehouse, task_id=refresh_stages, run_id=manual__2024-08-09T07:13:50.906281+00:00, execution_date=20240809T071350, start_date=20240809T071425, end_date=20240809T071426
[2024-08-09T07:14:26.781+0000] {local_task_job_runner.py:240} INFO - Task exited with return code 0
[2024-08-09T07:14:26.843+0000] {taskinstance.py:3498} INFO - 2 downstream tasks scheduled from follow-on schedule check
[2024-08-09T07:14:26.856+0000] {local_task_job_runner.py:222} INFO - ::endgroup::
