[2024-08-07T05:58:54.199+0000] {local_task_job_runner.py:120} INFO - ::group::Pre task execution logs
[2024-08-07T05:58:54.235+0000] {taskinstance.py:2076} INFO - Dependencies all met for dep_context=non-requeueable deps ti=<TaskInstance: Integrate_Time_Location_Dimension.bronze_time manual__2024-08-07T05:58:41.757820+00:00 [queued]>
[2024-08-07T05:58:54.252+0000] {taskinstance.py:2076} INFO - Dependencies all met for dep_context=requeueable deps ti=<TaskInstance: Integrate_Time_Location_Dimension.bronze_time manual__2024-08-07T05:58:41.757820+00:00 [queued]>
[2024-08-07T05:58:54.252+0000] {taskinstance.py:2306} INFO - Starting attempt 1 of 1
[2024-08-07T05:58:54.290+0000] {taskinstance.py:2330} INFO - Executing <Task(PythonOperator): bronze_time> on 2024-08-07 05:58:41.757820+00:00
[2024-08-07T05:58:54.294+0000] {standard_task_runner.py:63} INFO - Started process 2581 to run task
[2024-08-07T05:58:54.298+0000] {standard_task_runner.py:90} INFO - Running: ['airflow', 'tasks', 'run', 'Integrate_Time_Location_Dimension', 'bronze_time', 'manual__2024-08-07T05:58:41.757820+00:00', '--job-id', '154', '--raw', '--subdir', 'DAGS_FOLDER/etl_time_location_dag.py', '--cfg-path', '/tmp/tmpvifwq0fw']
[2024-08-07T05:58:54.301+0000] {standard_task_runner.py:91} INFO - Job 154: Subtask bronze_time
[2024-08-07T05:58:54.406+0000] {task_command.py:426} INFO - Running <TaskInstance: Integrate_Time_Location_Dimension.bronze_time manual__2024-08-07T05:58:41.757820+00:00 [running]> on host 45f7764b2bf2
[2024-08-07T05:58:54.585+0000] {taskinstance.py:2648} INFO - Exporting env vars: AIRFLOW_CTX_DAG_OWNER='airflow' AIRFLOW_CTX_DAG_ID='Integrate_Time_Location_Dimension' AIRFLOW_CTX_TASK_ID='bronze_time' AIRFLOW_CTX_EXECUTION_DATE='2024-08-07T05:58:41.757820+00:00' AIRFLOW_CTX_TRY_NUMBER='1' AIRFLOW_CTX_DAG_RUN_ID='manual__2024-08-07T05:58:41.757820+00:00'
[2024-08-07T05:58:54.586+0000] {taskinstance.py:430} INFO - ::endgroup::
[2024-08-07T05:59:05.717+0000] {taskinstance.py:441} INFO - ::group::Post task execution logs
[2024-08-07T05:59:05.718+0000] {taskinstance.py:2905} ERROR - Task failed with exception
Traceback (most recent call last):
  File "/home/airflow/.local/lib/python3.11/site-packages/airflow/models/taskinstance.py", line 465, in _execute_task
    result = _execute_callable(context=context, **execute_callable_kwargs)
             ^^^^^^^^^^^^^^^^^^^^^^^^^^^^^^^^^^^^^^^^^^^^^^^^^^^^^^^^^^^^^
  File "/home/airflow/.local/lib/python3.11/site-packages/airflow/models/taskinstance.py", line 432, in _execute_callable
    return execute_callable(context=context, **execute_callable_kwargs)
           ^^^^^^^^^^^^^^^^^^^^^^^^^^^^^^^^^^^^^^^^^^^^^^^^^^^^^^^^^^^^
  File "/home/airflow/.local/lib/python3.11/site-packages/airflow/models/baseoperator.py", line 400, in wrapper
    return func(self, *args, **kwargs)
           ^^^^^^^^^^^^^^^^^^^^^^^^^^^
  File "/home/airflow/.local/lib/python3.11/site-packages/airflow/operators/python.py", line 235, in execute
    return_value = self.execute_callable()
                   ^^^^^^^^^^^^^^^^^^^^^^^
  File "/home/airflow/.local/lib/python3.11/site-packages/airflow/operators/python.py", line 252, in execute_callable
    return self.python_callable(*self.op_args, **self.op_kwargs)
           ^^^^^^^^^^^^^^^^^^^^^^^^^^^^^^^^^^^^^^^^^^^^^^^^^^^^^
  File "/opt/airflow/plugins/timelocation/load_date.py", line 13, in readTimeExcel
    .load(file)
     ^^^^^^^^^^
  File "/home/airflow/.local/lib/python3.11/site-packages/pyspark/sql/readwriter.py", line 307, in load
    return self._df(self._jreader.load(path))
                    ^^^^^^^^^^^^^^^^^^^^^^^^
  File "/home/airflow/.local/lib/python3.11/site-packages/py4j/java_gateway.py", line 1322, in __call__
    return_value = get_return_value(
                   ^^^^^^^^^^^^^^^^^
  File "/home/airflow/.local/lib/python3.11/site-packages/pyspark/errors/exceptions/captured.py", line 179, in deco
    return f(*a, **kw)
           ^^^^^^^^^^^
  File "/home/airflow/.local/lib/python3.11/site-packages/py4j/protocol.py", line 326, in get_return_value
    raise Py4JJavaError(
py4j.protocol.Py4JJavaError: An error occurred while calling o34.load.
: org.apache.spark.SparkClassNotFoundException: [DATA_SOURCE_NOT_FOUND] Failed to find the data source: excel. Please find packages at `https://spark.apache.org/third-party-projects.html`.
	at org.apache.spark.sql.errors.QueryExecutionErrors$.dataSourceNotFoundError(QueryExecutionErrors.scala:724)
	at org.apache.spark.sql.execution.datasources.DataSource$.lookupDataSource(DataSource.scala:647)
	at org.apache.spark.sql.execution.datasources.DataSource$.lookupDataSourceV2(DataSource.scala:697)
	at org.apache.spark.sql.DataFrameReader.load(DataFrameReader.scala:208)
	at org.apache.spark.sql.DataFrameReader.load(DataFrameReader.scala:186)
	at java.base/jdk.internal.reflect.NativeMethodAccessorImpl.invoke0(Native Method)
	at java.base/jdk.internal.reflect.NativeMethodAccessorImpl.invoke(NativeMethodAccessorImpl.java:77)
	at java.base/jdk.internal.reflect.DelegatingMethodAccessorImpl.invoke(DelegatingMethodAccessorImpl.java:43)
	at java.base/java.lang.reflect.Method.invoke(Method.java:568)
	at py4j.reflection.MethodInvoker.invoke(MethodInvoker.java:244)
	at py4j.reflection.ReflectionEngine.invoke(ReflectionEngine.java:374)
	at py4j.Gateway.invoke(Gateway.java:282)
	at py4j.commands.AbstractCommand.invokeMethod(AbstractCommand.java:132)
	at py4j.commands.CallCommand.execute(CallCommand.java:79)
	at py4j.ClientServerConnection.waitForCommands(ClientServerConnection.java:182)
	at py4j.ClientServerConnection.run(ClientServerConnection.java:106)
	at java.base/java.lang.Thread.run(Thread.java:840)
Caused by: java.lang.ClassNotFoundException: excel.DefaultSource
	at java.base/java.net.URLClassLoader.findClass(URLClassLoader.java:445)
	at java.base/java.lang.ClassLoader.loadClass(ClassLoader.java:592)
	at java.base/java.lang.ClassLoader.loadClass(ClassLoader.java:525)
	at org.apache.spark.sql.execution.datasources.DataSource$.$anonfun$lookupDataSource$5(DataSource.scala:633)
	at scala.util.Try$.apply(Try.scala:213)
	at org.apache.spark.sql.execution.datasources.DataSource$.$anonfun$lookupDataSource$4(DataSource.scala:633)
	at scala.util.Failure.orElse(Try.scala:224)
	at org.apache.spark.sql.execution.datasources.DataSource$.lookupDataSource(DataSource.scala:633)
	... 15 more

[2024-08-07T05:59:05.734+0000] {taskinstance.py:1206} INFO - Marking task as FAILED. dag_id=Integrate_Time_Location_Dimension, task_id=bronze_time, run_id=manual__2024-08-07T05:58:41.757820+00:00, execution_date=20240807T055841, start_date=20240807T055854, end_date=20240807T055905
[2024-08-07T05:59:05.767+0000] {standard_task_runner.py:110} ERROR - Failed to execute job 154 for task bronze_time (An error occurred while calling o34.load.
: org.apache.spark.SparkClassNotFoundException: [DATA_SOURCE_NOT_FOUND] Failed to find the data source: excel. Please find packages at `https://spark.apache.org/third-party-projects.html`.
	at org.apache.spark.sql.errors.QueryExecutionErrors$.dataSourceNotFoundError(QueryExecutionErrors.scala:724)
	at org.apache.spark.sql.execution.datasources.DataSource$.lookupDataSource(DataSource.scala:647)
	at org.apache.spark.sql.execution.datasources.DataSource$.lookupDataSourceV2(DataSource.scala:697)
	at org.apache.spark.sql.DataFrameReader.load(DataFrameReader.scala:208)
	at org.apache.spark.sql.DataFrameReader.load(DataFrameReader.scala:186)
	at java.base/jdk.internal.reflect.NativeMethodAccessorImpl.invoke0(Native Method)
	at java.base/jdk.internal.reflect.NativeMethodAccessorImpl.invoke(NativeMethodAccessorImpl.java:77)
	at java.base/jdk.internal.reflect.DelegatingMethodAccessorImpl.invoke(DelegatingMethodAccessorImpl.java:43)
	at java.base/java.lang.reflect.Method.invoke(Method.java:568)
	at py4j.reflection.MethodInvoker.invoke(MethodInvoker.java:244)
	at py4j.reflection.ReflectionEngine.invoke(ReflectionEngine.java:374)
	at py4j.Gateway.invoke(Gateway.java:282)
	at py4j.commands.AbstractCommand.invokeMethod(AbstractCommand.java:132)
	at py4j.commands.CallCommand.execute(CallCommand.java:79)
	at py4j.ClientServerConnection.waitForCommands(ClientServerConnection.java:182)
	at py4j.ClientServerConnection.run(ClientServerConnection.java:106)
	at java.base/java.lang.Thread.run(Thread.java:840)
Caused by: java.lang.ClassNotFoundException: excel.DefaultSource
	at java.base/java.net.URLClassLoader.findClass(URLClassLoader.java:445)
	at java.base/java.lang.ClassLoader.loadClass(ClassLoader.java:592)
	at java.base/java.lang.ClassLoader.loadClass(ClassLoader.java:525)
	at org.apache.spark.sql.execution.datasources.DataSource$.$anonfun$lookupDataSource$5(DataSource.scala:633)
	at scala.util.Try$.apply(Try.scala:213)
	at org.apache.spark.sql.execution.datasources.DataSource$.$anonfun$lookupDataSource$4(DataSource.scala:633)
	at scala.util.Failure.orElse(Try.scala:224)
	at org.apache.spark.sql.execution.datasources.DataSource$.lookupDataSource(DataSource.scala:633)
	... 15 more
; 2581)
[2024-08-07T05:59:05.780+0000] {local_task_job_runner.py:240} INFO - Task exited with return code 1
[2024-08-07T05:59:05.853+0000] {taskinstance.py:3498} INFO - 0 downstream tasks scheduled from follow-on schedule check
[2024-08-07T05:59:05.883+0000] {local_task_job_runner.py:222} INFO - ::endgroup::
