[2024-08-07T08:06:57.448+0000] {local_task_job_runner.py:120} INFO - ::group::Pre task execution logs
[2024-08-07T08:06:57.488+0000] {taskinstance.py:2076} INFO - Dependencies all met for dep_context=non-requeueable deps ti=<TaskInstance: Integrate_Time_Location_Dimension.query_postgres_database manual__2024-08-07T08:06:33.881776+00:00 [queued]>
[2024-08-07T08:06:57.507+0000] {taskinstance.py:2076} INFO - Dependencies all met for dep_context=requeueable deps ti=<TaskInstance: Integrate_Time_Location_Dimension.query_postgres_database manual__2024-08-07T08:06:33.881776+00:00 [queued]>
[2024-08-07T08:06:57.507+0000] {taskinstance.py:2306} INFO - Starting attempt 1 of 1
[2024-08-07T08:06:57.544+0000] {taskinstance.py:2330} INFO - Executing <Task(SQLExecuteQueryOperator): query_postgres_database> on 2024-08-07 08:06:33.881776+00:00
[2024-08-07T08:06:57.549+0000] {standard_task_runner.py:63} INFO - Started process 5007 to run task
[2024-08-07T08:06:57.553+0000] {standard_task_runner.py:90} INFO - Running: ['airflow', 'tasks', 'run', 'Integrate_Time_Location_Dimension', 'query_postgres_database', 'manual__2024-08-07T08:06:33.881776+00:00', '--job-id', '195', '--raw', '--subdir', 'DAGS_FOLDER/etl_time_location.dag.py', '--cfg-path', '/tmp/tmpz43ep3ak']
[2024-08-07T08:06:57.555+0000] {standard_task_runner.py:91} INFO - Job 195: Subtask query_postgres_database
[2024-08-07T08:06:57.649+0000] {task_command.py:426} INFO - Running <TaskInstance: Integrate_Time_Location_Dimension.query_postgres_database manual__2024-08-07T08:06:33.881776+00:00 [running]> on host 45f7764b2bf2
[2024-08-07T08:06:57.798+0000] {taskinstance.py:2648} INFO - Exporting env vars: AIRFLOW_CTX_DAG_OWNER='airflow' AIRFLOW_CTX_DAG_ID='Integrate_Time_Location_Dimension' AIRFLOW_CTX_TASK_ID='query_postgres_database' AIRFLOW_CTX_EXECUTION_DATE='2024-08-07T08:06:33.881776+00:00' AIRFLOW_CTX_TRY_NUMBER='1' AIRFLOW_CTX_DAG_RUN_ID='manual__2024-08-07T08:06:33.881776+00:00'
[2024-08-07T08:06:57.799+0000] {taskinstance.py:430} INFO - ::endgroup::
[2024-08-07T08:06:57.812+0000] {sql.py:276} INFO - Executing: INSERT INTO stgDimLocation(LocationKey, region_code, region_name,
                            province_code, province_name,
                            district_code, district_name,
                            ward_code, ward_name)
SELECT
	*
FROM dblink('dbname=atvsld password=nhanbui user=postgres port=5434', 'select * from public.vw_stgdimlocation')
AS (
	LocationKey BIGINT,
	region_code CHAR(5),
	region_name VARCHAR(50),
	province_code CHAR(5),
	province_name VARCHAR(50),
	district_code CHAR(5),
	district_name VARCHAR(50),
	ward_code CHAR(5),
	ward_name VARCHAR(50)
);
[2024-08-07T08:06:57.826+0000] {base.py:84} INFO - Using connection ID 'postgres_hongheovna' for task execution.
[2024-08-07T08:06:57.924+0000] {base.py:84} INFO - Using connection ID 'postgres_hongheovna' for task execution.
[2024-08-07T08:06:57.945+0000] {sql.py:470} INFO - Running statement: INSERT INTO stgDimLocation(LocationKey, region_code, region_name,
                            province_code, province_name,
                            district_code, district_name,
                            ward_code, ward_name)
SELECT
	*
FROM dblink('dbname=atvsld password=*** user=postgres port=5434', 'select * from public.vw_stgdimlocation')
AS (
	LocationKey BIGINT,
	region_code CHAR(5),
	region_name VARCHAR(50),
	province_code CHAR(5),
	province_name VARCHAR(50),
	district_code CHAR(5),
	district_name VARCHAR(50),
	ward_code CHAR(5),
	ward_name VARCHAR(50)
);, parameters: None
[2024-08-07T08:06:57.950+0000] {taskinstance.py:441} INFO - ::group::Post task execution logs
[2024-08-07T08:06:57.953+0000] {taskinstance.py:2905} ERROR - Task failed with exception
Traceback (most recent call last):
  File "/home/airflow/.local/lib/python3.11/site-packages/airflow/models/taskinstance.py", line 465, in _execute_task
    result = _execute_callable(context=context, **execute_callable_kwargs)
             ^^^^^^^^^^^^^^^^^^^^^^^^^^^^^^^^^^^^^^^^^^^^^^^^^^^^^^^^^^^^^
  File "/home/airflow/.local/lib/python3.11/site-packages/airflow/models/taskinstance.py", line 432, in _execute_callable
    return execute_callable(context=context, **execute_callable_kwargs)
           ^^^^^^^^^^^^^^^^^^^^^^^^^^^^^^^^^^^^^^^^^^^^^^^^^^^^^^^^^^^^
  File "/home/airflow/.local/lib/python3.11/site-packages/airflow/models/baseoperator.py", line 400, in wrapper
    return func(self, *args, **kwargs)
           ^^^^^^^^^^^^^^^^^^^^^^^^^^^
  File "/home/airflow/.local/lib/python3.11/site-packages/airflow/providers/common/sql/operators/sql.py", line 282, in execute
    output = hook.run(
             ^^^^^^^^^
  File "/home/airflow/.local/lib/python3.11/site-packages/airflow/providers/common/sql/hooks/sql.py", line 418, in run
    self._run_command(cur, sql_statement, parameters)
  File "/home/airflow/.local/lib/python3.11/site-packages/airflow/providers/common/sql/hooks/sql.py", line 475, in _run_command
    cur.execute(sql_statement)
psycopg2.errors.UndefinedTable: relation "stgdimlocation" does not exist
LINE 1: INSERT INTO stgDimLocation(LocationKey, region_code, region_...
                    ^

[2024-08-07T08:06:57.969+0000] {taskinstance.py:1206} INFO - Marking task as FAILED. dag_id=Integrate_Time_Location_Dimension, task_id=query_postgres_database, run_id=manual__2024-08-07T08:06:33.881776+00:00, execution_date=20240807T080633, start_date=20240807T080657, end_date=20240807T080657
[2024-08-07T08:06:58.008+0000] {standard_task_runner.py:110} ERROR - Failed to execute job 195 for task query_postgres_database (relation "stgdimlocation" does not exist
LINE 1: INSERT INTO stgDimLocation(LocationKey, region_code, region_...
                    ^
; 5007)
[2024-08-07T08:06:58.047+0000] {local_task_job_runner.py:240} INFO - Task exited with return code 1
[2024-08-07T08:06:58.086+0000] {taskinstance.py:3498} INFO - 0 downstream tasks scheduled from follow-on schedule check
[2024-08-07T08:06:58.106+0000] {local_task_job_runner.py:222} INFO - ::endgroup::
